Workbook

Sheet data
A1: group | B1: land | C1: trial | D1: onbd | E1: conv | F1: rev | G1: supflag | H1: refund | I1: eng | J1: days | K1: region | L1: device | M1: plan | N1: tickets
A2: Control | B2: 0 | C2: 0 | D2: 0 | E2: 0 | F2: 0 | G2: 0 | H2: 0 | I2: 45.7 | K2: North | L2: Desktop | M2: Basic | N2: 0
A3: Control | B3: 1 | C3: 0 | D3: 0 | E3: 0 | F3: 0 | G3: 0 | H3: 0 | I3: 48.6 | K3: West | L3: Mobile | M3: Free | N3: 0
A4: Control | B4: 1 | C4: 0 | D4: 0 | E4: 0 | F4: 0 | G4: 1 | H4: 0 | I4: 35.4 | K4: East | L4: Mobile | M4: Premium | N4: 1
A5: Control | B5: 1 | C5: 0 | D5: 0 | E5: 0 | F5: 0 | G5: 0 | H5: 0 | I5: 64.6 | K5: South | L5: Mobile | M5: Basic | N5: 0
A6: Control | B6: 0 | C6: 0 | D6: 0 | E6: 0 | F6: 0 | G6: 0 | H6: 0 | I6: 66.6 | K6: North | L6: Tablet | M6: Free | N6: 0
A7: Control | B7: 1 | C7: 0 | D7: 0 | E7: 0 | F7: 0 | G7: 0 | H7: 0 | I7: 40.8 | K7: East | L7: Mobile | M7: Premium | N7: 0
A8: Control | B8: 1 | C8: 1 | D8: 0 | E8: 0 | F8: 0 | G8: 0 | H8: 0 | I8: 57.1 | K8: East | L8: Mobile | M8: Basic | N8: 0
A9: Control | B9: 0 | C9: 0 | D9: 0 | E9: 0 | F9: 0 | G9: 0 | H9: 0 | I9: 36.4 | K9: South | L9: Mobile | M9: Free | N9: 0
A10: Control | B10: 0 | C10: 0 | D10: 0 | E10: 0 | F10: 0 | G10: 0 | H10: 0 | I10: 55.4 | K10: South | L10: Tablet | M10: Basic | N10: 0
A11: Control | B11: 1 | C11: 0 | D11: 0 | E11: 0 | F11: 0 | G11: 0 | H11: 0 | I11: 57.3 | K11: West | L11: Desktop | M11: Free | N11: 0
A12: Control | B12: 1 | C12: 1 | D12: 1 | E12: 0 | F12: 0 | G12: 0 | H12: 0 | I12: 63.6 | K12: East | L12: Mobile | M12: Basic | N12: 0
A13: Control | B13: 1 | C13: 1 | D13: 1 | E13: 0 | F13: 0 | G13: 1 | H13: 0 | I13: 80.4 | K13: East | L13: Mobile | M13: Premium | N13: 1
... A60: Control | B60: 0 | C60: 0 | D60: 0 | E60: 0 | F60: 0 | G60: 1 | H60: 0 | I60: 48.9 | K60: North | L60: Mobile | M60: Free | N60: 2
A61: Control | B61: 1 | C61: 1 | D61: 1 | E61: 1 | F61: 240.42 | G61: 0 | H61: 0 | I61: 56.5 | J61: 16 | K61: West | L61: Mobile | M61: Free | N61: 0
A62: Control | B62: 1 | C62: 0 | D62: 0 | E62: 0 | F62: 0 | G62: 0 | H62: 0 | I62: 53.7 | K62: South | L62: Mobile | M62: Free | N62: 0
A63: Control | B63: 0 | C63: 0 | D63: 0 | E63: 0 | F63: 0 | G63: 0 | H63: 0 | I63: 62.2 | K63: North | L63: Mobile | M63: Premium | N63: 0
A64: Control | B64: 1 | C64: 0 | D64: 0 | E64: 0 | F64: 0 | G64: 0 | H64: 0 | I64: 50.2 | K64: South | L64: Desktop | M64: Free | N64: 0
A65: Control | B65: 1 | C65: 0 | D65: 0 | E65: 0 | F65: 0 | G65: 0 | H65: 0 | I65: 74.3 | K65: North | L65: Mobile | M65: Basic | N65: 0
A66: Control | B66: 1 | C66: 0 | D66: 0 | E66: 0 | F66: 0 | G66: 0 | H66: 0 | I66: 58 | K66: South | L66: Desktop | M66: Free | N66: 0
A67: Control | B67: 0 | C67: 0 | D67: 0 | E67: 0 | F67: 0 | G67: 0 | H67: 0 | I67: 46.7 | K67: South | L67: Mobile | M67: Free | N67: 0
A68: Control | B68: 1 | C68: 0 | D68: 0 | E68: 0 | F68: 0 | G68: 1 | H68: 0 | I68: 49.6 | K68: South | L68: Desktop | M68: Premium | N68: 1
A69: Control | B69: 0 | C69: 0 | D69: 0 | E69: 0 | F69: 0 | G69: 0 | H69: 0 | I69: 60.4 | K69: West | L69: Mobile | M69: Free | N69: 0
A70: Control | B70: 1 | C70: 1 | D70: 1 | E70: 0 | F70: 0 | G70: 0 | H70: 0 | I70: 55.3 | K70: East | L70: Desktop | M70: Free | N70: 0
A71: Control | B71: 0 | C71: 0 | D71: 0 | E71: 0 | F71: 0 | G71: 0 | H71: 0 | I71: 56.2 | K71: North | L71: Desktop | M71: Free | N71: 0
A72: Control | B72: 0 | C72: 0 | D72: 0 | E72: 0 | F72: 0 | G72: 0 | H72: 0 | I72: 29.4 | K72: West | L72: Mobile | M72: Free | N72: 0
A73: Control | B73: 1 | C73: 0 | D73: 0 | E73: 0 | F73: 0 | G73: 0 | H73: 0 | I73: 54.2 | K73: East | L73: Mobile | M73: Free | N73: 0
... A79: Control | B79: 0 | C79: 0 | D79: 0 | E79: 0 | F79: 0 | G79: 1 | H79: 0 | I79: 48.4 | K79: North | L79: Mobile | M79: Free | N79: 2
A80: Control | B80: 1 | C80: 1 | D80: 1 | E80: 1 | F80: 457.51 | G80: 0 | H80: 0 | I80: 38 | J80: 7 | K80: West | L80: Desktop | M80: Free | N80: 0
A81: Control | B81: 1 | C81: 0 | D81: 0 | E81: 0 | F81: 0 | G81: 0 | H81: 0 | I81: 44.2 | K81: East | L81: Mobile | M81: Free | N81: 0
A82: Control | B82: 1 | C82: 1 | D82: 1 | E82: 0 | F82: 0 | G82: 0 | H82: 0 | I82: 81.2 | K82: South | L82: Mobile | M82: Free | N82: 0
A83: Control | B83: 1 | C83: 1 | D83: 0 | E83: 0 | F83: 0 | G83: 0 | H83: 0 | I83: 63.8 | K83: South | L83: Mobile | M83: Free | N83: 0
A84: Control | B84: 0 | C84: 0 | D84: 0 | E84: 0 | F84: 0 | G84: 0 | H84: 0 | I84: 64.7 | K84: South | L84: Desktop | M84: Free | N84: 0
A85: Control | B85: 0 | C85: 0 | D85: 0 | E85: 0 | F85: 0 | G85: 0 | H85: 0 | I85: 60.4 | K85: West | L85: Mobile | M85: Basic | N85: 0
A86: Control | B86: 0 | C86: 0 | D86: 0 | E86: 0 | F86: 0 | G86: 0 | H86: 0 | I86: 66.6 | K86: South | L86: Mobile | M86: Free | N86: 0
A87: Control | B87: 1 | C87: 0 | D87: 0 | E87: 0 | F87: 0 | G87: 0 | H87: 0 | I87: 50.9 | K87: North | L87: Desktop | M87: Free | N87: 0
A88: Control | B88: 0 | C88: 0 | D88: 0 | E88: 0 | F88: 0 | G88: 0 | H88: 0 | I88: 51 | K88: West | L88: Desktop | M88: Basic | N88: 0
A89: Control | B89: 0 | C89: 0 | D89: 0 | E89: 0 | F89: 0 | G89: 0 | H89: 0 | I89: 65.8 | K89: South | L89: Mobile | M89: Premium | N89: 0
A90: Control | B90: 1 | C90: 0 | D90: 0 | E90: 0 | F90: 0 | G90: 0 | H90: 0 | I90: 61.8 | K90: North | L90: Mobile | M90: Basic | N90: 0
A91: Control | B91: 1 | C91: 0 | D91: 0 | E91: 0 | F91: 0 | G91: 0 | H91: 0 | I91: 54.5 | K91: North | L91: Mobile | M91: Basic | N91: 0
...

Sheet summary_metrics
A1: Control vs Treatment — Experiment Summary
A2: Live formulas over the data sheet. Rates are proportions; ARPU/ARPCU in revenue units.
A4: Metric | B4: Control | C4: Treatment | D4: Abs Diff | E4: Rel Diff
A5: User count | B5: =COUNTIFS(data!$A$2:$A$1401,"Control") -> 690 | C5: =COUNTIFS(data!$A$2:$A$1401,"Treatment") -> 710 | D5: =C5-B5 -> 20 | E5: =IFERROR((C5-B5)/B5,0) -> 0.028985507
A6: Landing page visit rate | B6: =AVERAGEIFS(data!$B$2:$B$1401,data!$A$2:$A$1401,"Control") -> 0.63623188 | C6: =AVERAGEIFS(data!$B$2:$B$1401,data!$A$2:$A$1401,"Treatment") -> 0.72394366 | D6: =C6-B6 -> 0.087711778 | E6: =IFERROR((C6-B6)/B6,0) -> 0.13786134
A7: Trial start rate | B7: =AVERAGEIFS(data!$C$2:$C$1401,data!$A$2:$A$1401,"Control") -> 0.25072464 | C7: =AVERAGEIFS(data!$C$2:$C$1401,data!$A$2:$A$1401,"Treatment") -> 0.29014085 | D7: =C7-B7 -> 0.039416207 | E7: =IFERROR((C7-B7)/B7,0) -> 0.15720915
A8: Onboarding completion rate | B8: =AVERAGEIFS(data!$D$2:$D$1401,data!$A$2:$A$1401,"Control") -> 0.15652174 | C8: =AVERAGEIFS(data!$D$2:$D$1401,data!$A$2:$A$1401,"Treatment") -> 0.21126761 | D8: =C8-B8 -> 0.054745867 | E8: =IFERROR((C8-B8)/B8,0) -> 0.34976526
A9: Paid conversion rate | B9: =AVERAGEIFS(data!$E$2:$E$1401,data!$A$2:$A$1401,"Control") -> 0.031884058 | C9: =AVERAGEIFS(data!$E$2:$E$1401,data!$A$2:$A$1401,"Treatment") -> 0.070422535 | D9: =C9-B9 -> 0.038538477 | E9: =IFERROR((C9-B9)/B9,0) -> 1.2087068
A10: Avg revenue per user (ARPU) | B10: =AVERAGEIFS(data!$F$2:$F$1401,data!$A$2:$A$1401,"Control") -> 51.974319 | C10: =AVERAGEIFS(data!$F$2:$F$1401,data!$A$2:$A$1401,"Treatment") -> 54.254521 | D10: =C10-B10 -> 2.2802023 | E10: =IFERROR((C10-B10)/B10,0) -> 0.043871711
A11: Avg revenue per converted user (ARPCU) | B11: =AVERAGEIFS(data!$F$2:$F$1401,data!$A$2:$A$1401,"Control",data!$E$2:$E$1401,1) -> 1630.1036 | C11: =AVERAGEIFS(data!$F$2:$F$1401,data!$A$2:$A$1401,"Treatment",data!$E$2:$E$1401,1) -> 770.4142 | D11: =C11-B11 -> -859.68944 | E11: =IFERROR((C11-B11)/B11,0) -> -0.5273833
A12: Refund rate | B12: =AVERAGEIFS(data!$H$2:$H$1401,data!$A$2:$A$1401,"Control") -> 0 | C12: =AVERAGEIFS(data!$H$2:$H$1401,data!$A$2:$A$1401,"Treatment") -> 0.0042253521 | D12: =C12-B12 -> 0.0042253521 | E12: =IFERROR((C12-B12)/B12,0) -> 0
A13: Support ticket rate (users w/ >0) | B13: =AVERAGEIFS(data!$G$2:$G$1401,data!$A$2:$A$1401,"Control") -> 0.14782609 | C13: =AVERAGEIFS(data!$G$2:$G$1401,data!$A$2:$A$1401,"Treatment") -> 0.24788732 | D13: =C13-B13 -> 0.10006124 | E13: =IFERROR((C13-B13)/B13,0) -> 0.67688484
A14: Support tickets per user | B14: =AVERAGEIFS(data!$N$2:$N$1401,data!$A$2:$A$1401,"Control") -> 0.22028986 | C14: =AVERAGEIFS(data!$N$2:$N$1401,data!$A$2:$A$1401,"Treatment") -> 0.37323944 | D14: =C14-B14 -> 0.15294958 | E14: =IFERROR((C14-B14)/B14,0) -> 0.6943106
A15: Avg engagement score | B15: =AVERAGEIFS(data!$I$2:$I$1401,data!$A$2:$A$1401,"Control") -> 57.029532 | C15: =AVERAGEIFS(data!$I$2:$I$1401,data!$A$2:$A$1401,"Treatment") -> 62.940028 | D15: =C15-B15 -> 5.9104963 | E15: =IFERROR((C15-B15)/B15,0) -> 0.10363922
A16: Avg days to convert | B16: =AVERAGEIFS(data!$J$2:$J$1401,data!$A$2:$A$1401,"Control",data!$E$2:$E$1401,1) -> 8.8636364 | C16: =AVERAGEIFS(data!$J$2:$J$1401,data!$A$2:$A$1401,"Treatment",data!$E$2:$E$1401,1) -> 6.4 | D16: =C16-B16 -> -2.4636364 | E16: =IFERROR((C16-B16)/B16,0) -> -0.27794872
A17: Converted users (count) | B17: =COUNTIFS(data!$A$2:$A$1401,"Control",data!$E$2:$E$1401,1) -> 22 | C17: =COUNTIFS(data!$A$2:$A$1401,"Treatment",data!$E$2:$E$1401,1) -> 50 | D17: =C17-B17 -> 28 | E17: =IFERROR((C17-B17)/B17,0) -> 1.2727273

Sheet hypothesis_test
A1: Two-Proportion Z-Test — Paid Conversion Rate
A2: H0: p(Treatment)=p(Control) H1: p(Treatment)≠p(Control) α=0.05 (two-tailed)
A5: Control users (n_c) | B5: =COUNTIFS(data!$A$2:$A$1401,"Control") -> 690
A6: Control conversions (x_c) | B6: =COUNTIFS(data!$A$2:$A$1401,"Control",data!$E$2:$E$1401,1) -> 22
A7: Treatment users (n_t) | B7: =COUNTIFS(data!$A$2:$A$1401,"Treatment") -> 710
A8: Treatment conversions (x_t) | B8: =COUNTIFS(data!$A$2:$A$1401,"Treatment",data!$E$2:$E$1401,1) -> 50
A9: p_control | B9: =B6/B5 -> 0.031884058
A10: p_treatment | B10: =B8/B7 -> 0.070422535
A11: Absolute uplift | B11: =B10-B9 -> 0.038538477
A12: Relative uplift | B12: =IFERROR((B10-B9)/B9,0) -> 1.2087068
A13: Pooled p | B13: =(B6+B8)/(B5+B7) -> 0.051428571
A14: Std error | B14: =SQRT(B13*(1-B13)*(1/B5+1/B7)) -> 0.011807217
A15: Z statistic | B15: =(B10-B9)/B14 -> 3.2639763
A16: P-value (two-tailed) | B16: =2*(1-NORMSDIST(ABS(B15))) -> 0.0010986034
A17: Decision (α=0.05) | B17: =IF(B16<0.05,"Reject H0 — statistically significant","Fail to reject H0") -> Reject H0 — statistically significant

Sheet guardrails
A1: Guardrail Metrics — Risk Evaluation
A2: A conversion win is only safe if guardrails hold. Direction matters per metric.
A4: Guardrail | B4: Control | C4: Treatment | D4: Change | E4: Risk?
A5: Refund rate | B5: =AVERAGEIFS(data!$H$2:$H$1401,data!$A$2:$A$1401,"Control") -> 0 | C5: =AVERAGEIFS(data!$H$2:$H$1401,data!$A$2:$A$1401,"Treatment") -> 0.0042253521 | D5: =C5-B5 -> 0.0042253521 | E5: Low — stays <1%
A6: Support ticket rate | B6: =AVERAGEIFS(data!$G$2:$G$1401,data!$A$2:$A$1401,"Control") -> 0.14782609 | C6: =AVERAGEIFS(data!$G$2:$G$1401,data!$A$2:$A$1401,"Treatment") -> 0.24788732 | D6: =C6-B6 -> 0.10006124 | E6: HIGH — nearly doubles; staffing impact
A7: Support tickets per user | B7: =AVERAGEIFS(data!$N$2:$N$1401,data!$A$2:$A$1401,"Control") -> 0.22028986 | C7: =AVERAGEIFS(data!$N$2:$N$1401,data!$A$2:$A$1401,"Treatment") -> 0.37323944 | D7: =C7-B7 -> 0.15294958 | E7: HIGH — more load per user
A8: ARPCU (revenue/converted) | B8: =AVERAGEIFS(data!$F$2:$F$1401,data!$A$2:$A$1401,"Control",data!$E$2:$E$1401,1) -> 1630.1036 | C8: =AVERAGEIFS(data!$F$2:$F$1401,data!$A$2:$A$1401,"Treatment",data!$E$2:$E$1401,1) -> 770.4142 | D8: =C8-B8 -> -859.68944 | E8: MEDIUM — lower-value converts
A9: Avg days to convert | B9: =AVERAGEIFS(data!$J$2:$J$1401,data!$A$2:$A$1401,"Control",data!$E$2:$E$1401,1) -> 8.8636364 | C9: =AVERAGEIFS(data!$J$2:$J$1401,data!$A$2:$A$1401,"Treatment",data!$E$2:$E$1401,1) -> 6.4 | D9: =C9-B9 -> -2.4636364 | E9: Positive — faster activation
A10: Avg engagement score | B10: =AVERAGEIFS(data!$I$2:$I$1401,data!$A$2:$A$1401,"Control") -> 57.029532 | C10: =AVERAGEIFS(data!$I$2:$I$1401,data!$A$2:$A$1401,"Treatment") -> 62.940028 | D10: =C10-B10 -> 5.9104963 | E10: Positive — higher engagement

Sheet segment_analysis
A1: Segment-Level Analysis (≥3 metrics by segment)
A3: Paid conversion rate by Region
A4: Segment | B4: Control | C4: Treatment | D4: Abs Diff
A5: North | B5: =AVERAGEIFS(data!$E$2:$E$1401,data!$K$2:$K$1401,"North",data!$A$2:$A$1401,"Control") -> 0.034825871 | C5: =AVERAGEIFS(data!$E$2:$E$1401,data!$K$2:$K$1401,"North",data!$A$2:$A$1401,"Treatment") -> 0.088888889 | D5: =C5-B5 -> 0.054063018
A6: South | B6: =AVERAGEIFS(data!$E$2:$E$1401,data!$K$2:$K$1401,"South",data!$A$2:$A$1401,"Control") -> 0.032608696 | C6: =AVERAGEIFS(data!$E$2:$E$1401,data!$K$2:$K$1401,"South",data!$A$2:$A$1401,"Treatment") -> 0.076502732 | D6: =C6-B6 -> 0.043894037
A7: East | B7: =AVERAGEIFS(data!$E$2:$E$1401,data!$K$2:$K$1401,"East",data!$A$2:$A$1401,"Control") -> 0.025477707 | C7: =AVERAGEIFS(data!$E$2:$E$1401,data!$K$2:$K$1401,"East",data!$A$2:$A$1401,"Treatment") -> 0.064705882 | D7: =C7-B7 -> 0.039228175
A8: West | B8: =AVERAGEIFS(data!$E$2:$E$1401,data!$K$2:$K$1401,"West",data!$A$2:$A$1401,"Control") -> 0.033783784 | C8: =AVERAGEIFS(data!$E$2:$E$1401,data!$K$2:$K$1401,"West",data!$A$2:$A$1401,"Treatment") -> 0.050847458 | D8: =C8-B8 -> 0.017063674
A10: Paid conversion rate by Device
A11: Segment | B11: Control | C11: Treatment | D11: Abs Diff
A12: Desktop | B12: =AVERAGEIFS(data!$E$2:$E$1401,data!$L$2:$L$1401,"Desktop",data!$A$2:$A$1401,"Control") -> 0.045 | C12: =AVERAGEIFS(data!$E$2:$E$1401,data!$L$2:$L$1401,"Desktop",data!$A$2:$A$1401,"Treatment") -> 0.0657277 | D12: =C12-B12 -> 0.0207277
A13: Mobile | B13: =AVERAGEIFS(data!$E$2:$E$1401,data!$L$2:$L$1401,"Mobile",data!$A$2:$A$1401,"Control") -> 0.025821596 | C13: =AVERAGEIFS(data!$E$2:$E$1401,data!$L$2:$L$1401,"Mobile",data!$A$2:$A$1401,"Treatment") -> 0.074074074 | D13: =C13-B13 -> 0.048252478
A14: Tablet | B14: =AVERAGEIFS(data!$E$2:$E$1401,data!$L$2:$L$1401,"Tablet",data!$A$2:$A$1401,"Control") -> 0.018181818 | C14: =AVERAGEIFS(data!$E$2:$E$1401,data!$L$2:$L$1401,"Tablet",data!$A$2:$A$1401,"Treatment") -> 0.071428571 | D14: =C14-B14 -> 0.053246753
A16: ARPU by Region
A17: Segment | B17: Control | C17: Treatment | D17: Abs Diff
A18: North | B18: =AVERAGEIFS(data!$F$2:$F$1401,data!$K$2:$K$1401,"North",data!$A$2:$A$1401,"Control") -> 84.5001 | C18: =AVERAGEIFS(data!$F$2:$F$1401,data!$K$2:$K$1401,"North",data!$A$2:$A$1401,"Treatment") -> 80.9675 | D18: =C18-B18 -> -3.5325995
A19: South | B19: =AVERAGEIFS(data!$F$2:$F$1401,data!$K$2:$K$1401,"South",data!$A$2:$A$1401,"Control") -> 76.033098 | C19: =AVERAGEIFS(data!$F$2:$F$1401,data!$K$2:$K$1401,"South",data!$A$2:$A$1401,"Treatment") -> 47.258525 | D19: =C19-B19 -> -28.774573
A20: East | B20: =AVERAGEIFS(data!$F$2:$F$1401,data!$K$2:$K$1401,"East",data!$A$2:$A$1401,"Control") -> 18.231465 | C20: =AVERAGEIFS(data!$F$2:$F$1401,data!$K$2:$K$1401,"East",data!$A$2:$A$1401,"Treatment") -> 47.051765 | D20: =C20-B20 -> 28.8203
A21: West | B21: =AVERAGEIFS(data!$F$2:$F$1401,data!$K$2:$K$1401,"West",data!$A$2:$A$1401,"Control") -> 13.684662 | C21: =AVERAGEIFS(data!$F$2:$F$1401,data!$K$2:$K$1401,"West",data!$A$2:$A$1401,"Treatment") -> 41.239831 | D21: =C21-B21 -> 27.555168
